<mujoco model="3">
    <compiler angle="radian" />
    <size njmax="500" nconmax="100" />
    <asset>
        <mesh name="base_link" file="base_link.STL" />
        <mesh name="thumb_Link" file="thumb_Link.STL" />
        <mesh name="thumb_Link1" file="thumb_Link1.STL" />
        <mesh name="thumb_Link2" file="thumb_Link2.STL" />
        <mesh name="thumb_Link3" file="thumb_Link3.STL" />
        <mesh name="middle_Link" file="middle_Link.STL" />
        <mesh name="middle_Link1" file="middle_Link1.STL" />
        <mesh name="middle_Link2" file="middle_Link2.STL" />
        <mesh name="middle_Link3" file="middle_Link3.STL" />
        <mesh name="index_Link" file="index_Link.STL" />
        <mesh name="index_Link1" file="index_Link1.STL" />
        <mesh name="index_Link2" file="index_Link2.STL" />
        <mesh name="index_Link3" file="index_Link3.STL" />
    </asset>
    <worldbody>
        <geom type="mesh" rgba="0.752941 0.752941 0.752941 1" mesh="base_link" />
        <body name="thumb_Link" pos="-0.03 0 0.095" quat="-3.67321e-06 0 0 1">
            <inertial pos="0 0 -0.015" quat="0.5 0.5 -0.5 0.5" mass="0.00100531" diaginertia="6.53451e-08 4.10501e-08 4.10501e-08" />
            <joint name="thumb_joint0" pos="0 0 0" axis="0 0 1" range="0 1.05" />
            <geom type="mesh" rgba="0.752941 0.752941 0.752941 1" mesh="thumb_Link" />
            <body name="thumb_Link1" pos="0 0 0" quat="0.707105 0.707108 0 0">
                <inertial pos="0.016 0 0" quat="0.5 0.5 0.5 0.5" mass="0.0142417" diaginertia="2.85162e-06 2.85162e-06 6.70206e-07" />
                <joint name="thumb_joint1" pos="0 0 0" axis="0 0 1" limited="true" range="0 1.57" />
                <geom type="mesh" rgba="0.752941 0.752941 0.752941 1" mesh="thumb_Link1" />
                <body name="thumb_Link2" pos="0.032 0 0">
                    <inertial pos="0.0275 0 0" quat="0.5 0.5 0.5 0.5" mass="0.00890105" diaginertia="8.44927e-07 8.44927e-07 4.03173e-07" />
                    <joint name="thumb_joint2" pos="0 0 0" axis="0 0 1" limited="true" range="0 1.57" />
                    <geom type="mesh" rgba="0.752941 0.752941 0.752941 1" mesh="thumb_Link2" />
                    <body name="thumb_Link3" pos="0.035 0 0">
                        <inertial pos="0.0275 0 0" quat="0.5 0.5 0.5 0.5" mass="0.00890105" diaginertia="8.44927e-07 8.44927e-07 4.03173e-07" />
                        <joint name="thumb_joint3" pos="0 0 0" axis="0 0 1" limited="true" range="0 1.57" />
                        <geom type="mesh" rgba="0.752941 0.752941 0.752941 1" mesh="thumb_Link3" />
                    </body>
                </body>
            </body>
        </body>
        <body name="middle_Link" pos="0.015 0.025 0.095">
            <inertial pos="0 0.000980762 -0.015" quat="0.5 0.5 -0.5 0.5" mass="0.00100531" diaginertia="6.53451e-08 4.10501e-08 4.10501e-08" />
            <joint name="middle_joint0" pos="0 0 0" axis="0 0 1" range="0 1.05" />
            <geom type="mesh" rgba="0.752941 0.752941 0.752941 1" mesh="middle_Link" />
            <body name="middle_Link1" pos="0 0 0" quat="0.707105 0.707108 0 0">
                <inertial pos="0.016 0 0" quat="0.5 0.5 0.5 0.5" mass="0.0142417" diaginertia="2.85162e-06 2.85162e-06 6.70206e-07" />
                <joint name="middle_joint1" pos="0 0 0" axis="0 0 1" limited="true" range="0 1.57" />
                <geom type="mesh" rgba="0.752941 0.752941 0.752941 1" mesh="middle_Link1" />
                <body name="middle_Link2" pos="0.032 0 0">
                    <inertial pos="0.0275 0 0" quat="0.5 0.5 0.5 0.5" mass="0.00890105" diaginertia="8.44927e-07 8.44927e-07 4.03173e-07" />
                    <joint name="middle_joint2" pos="0 0 0" axis="0 0 1" limited="true" range="0 1.57" />
                    <geom type="mesh" rgba="0.752941 0.752941 0.752941 1" mesh="middle_Link2" />
                    <body name="middle_Link3" pos="0.035 0 0">
                        <inertial pos="0.0275 0 0" quat="0.5 0.5 0.5 0.5" mass="0.00890105" diaginertia="8.44927e-07 8.44927e-07 4.03173e-07" />
                        <joint name="middle_joint3" pos="0 0 0" axis="0 0 1" limited="true" range="0 1.57" />
                        <geom type="mesh" rgba="0.752941 0.752941 0.752941 1" mesh="middle_Link3" />
                    </body>
                </body>
            </body>
        </body>
        <body name="index_Link" pos="0.015 -0.026 0.095">
            <inertial pos="0 1.92379e-05 -0.015" quat="0.5 0.5 -0.5 0.5" mass="0.00100531" diaginertia="6.53451e-08 4.10501e-08 4.10501e-08" />
            <joint name="index_joint0" pos="0 0 0" axis="0 0 1" range="0 1.05" />
            <geom type="mesh" rgba="0.752941 0.752941 0.752941 1" mesh="index_Link" />
            <body name="index_Link1" pos="0 0 0" quat="0.707105 0.707108 0 0">
                <inertial pos="0.0159972 -0.000299757 0" quat="0.504662 0.504662 0.495294 0.495294" mass="0.0142417" diaginertia="2.85162e-06 2.85162e-06 6.70206e-07" />
                <joint name="index_joint1" pos="0 0 0" axis="0 0 1" limited="true" range="0 1.57" />
                <geom type="mesh" rgba="0.752941 0.752941 0.752941 1" mesh="index_Link1" />
                <body name="index_Link2" pos="0.031994 -0.00059951 0">
                    <inertial pos="0.0274952 -0.000515205 -1.80622e-11" quat="0.504662 0.504662 0.495294 0.495294" mass="0.00890105" diaginertia="8.44927e-07 8.44927e-07 4.03173e-07" />
                    <joint name="index_joint2" pos="0 0 0" axis="0 0 1" limited="true" range="0 1.57" />
                    <geom type="mesh" rgba="0.752941 0.752941 0.752941 1" mesh="index_Link2" />
                    <body name="index_Link3" pos="0.034994 -0.00065572 0">
                        <inertial pos="0.0274952 -0.000515205 -1.80622e-11" quat="0.504662 0.504662 0.495294 0.495294" mass="0.00890105" diaginertia="8.44927e-07 8.44927e-07 4.03173e-07" />
                        <joint name="index_joint3" pos="0 0 0" axis="0 0 1" limited="true" range="0 1.57" />
                        <geom type="mesh" rgba="0.752941 0.752941 0.752941 1" mesh="index_Link3" />
                    </body>
                </body>
            </body>
        </body>
    </worldbody>
    <actuator>
        <general name="thumb_joint00" joint="thumb_joint0" ctrlrange="-1.05 1.05" biastype="affine"  />
        <general name="index_joint00" joint="index_joint0" ctrlrange="-1.05 1.05" biastype="affine"  />
        <general name="middle_joint00" joint="middle_joint0" ctrlrange="-1.05 1.05" biastype="affine"  />
    </actuator>
</mujoco>
