<!--


MODEL: Univewrsal Robots UR5 + Robotiq S Model 3 Finger Gripper
AUTHOR: Andrea Franceschetti @IASLAB Research Group
UNIVERSITY: University of Padua
DEPARTMENT: Departement of Information Engineering DEI
Control Engineering / Automation Engineering

-->


<!--Link  MuJoCo modeling: http://www.mujoco.org/book/modeling.html-->

<mujoco model="ur5gripper">
    <compiler angle="radian"
              inertiafromgeom="true"
              texturedir="textures/"
              meshdir="mesh/visual/"/>
    <option timestep="2e-3"
            iterations="10"
            tolerance="1e-10"
            impratio="20"/>
    <size njmax="600" nconmax="150" nstack="300000"/>

    <default>
        <site rgba="0.8 0.6 0.7 0.3" type="ellipsoid" group="3"/>
        <geom contype='1' conaffinity='1' condim='4'  margin="1e-3" solref=".01 1" solimp=".99 .99 .01" />
        <joint armature="0.01" damping=".1"/>
        <default class="UR5">
            <joint damping='65'/>
        </default>
        <default class="UR5e">
            <joint damping='45'/>
        </default>
        <default class="GRIPPER">
            <joint damping='5'/>
        </default>
    </default>

    <visual>
        <map fogstart="3" fogend="5" znear="0.05"/>
        <quality shadowsize="2048"/>
        <scale framelength="0.1"
               framewidth="0.005"
               contactwidth="0.1"
               contactheight="0.005"
               forcewidth="0.01"
               />
    </visual>

    <!--Assets-->
    <asset>
        <!--Meshes-->
        <mesh name="base"           file="base.stl"     />
        <mesh name="shoulder"       file="shoulder.stl" />
        <mesh name="upperarm"       file="upperarm.stl" />
        <mesh name="forearm"        file="forearm.stl"  />
        <mesh name="wrist1"         file="wrist1.stl"   />
        <mesh name="wrist2"         file="wrist2.stl"   />
        <mesh name="wrist3"         file="wrist3.stl"   />
        <mesh name="gripperpalm"    file="palm.STL"     />
        <mesh name="link_0"         file="link_0.STL"   />
        <mesh name="link_1"         file="link_1.STL"   />
        <mesh name="link_2"         file="link_2.STL"   />
        <mesh name="link_3"         file="link_3.STL"   />
	<mesh name="base_link" file="base_link.STL" />
        <mesh name="thumb_Link" file="thumb_Link.STL" />
        <mesh name="thumb_Link1" file="thumb_Link1.STL" />
        <mesh name="thumb_Link2" file="thumb_Link2.STL" />
        <mesh name="thumb_Link3" file="thumb_Link3.STL" />
        <mesh name="middle_Link" file="middle_Link.STL" />
        <mesh name="middle_Link1" file="middle_Link1.STL" />
        <mesh name="middle_Link2" file="middle_Link2.STL" />
        <mesh name="middle_Link3" file="middle_Link3.STL" />
        <mesh name="index_Link" file="index_Link.STL" />
        <mesh name="index_Link1" file="index_Link1.STL" />
        <mesh name="index_Link2" file="index_Link2.STL" />
        <mesh name="index_Link3" file="index_Link3.STL" />
        <!--Textures-->
        <texture name="ur5_tex"     type="2d"       builtin="flat" height="32" width="32" rgb1="0.45 0.45 0.45" />
        <texture name="gripper_tex" type="2d"       builtin="flat" height="32" width="32" rgb1="0.45 0.45 0.45" rgb2="0 0 0"/>
        <texture name="bench_tex"   type="2d"       builtin="flat" height="32" width="32" rgb1="0.7 0.7 0.7" />
        <texture name="sky_tex"     type="skybox"   builtin="gradient" width="100" height="100" rgb1="1 1 1" rgb2="0.3 0.3 0.8" />
        <texture name="texgeom"     type="cube"     builtin="flat" mark="cross" width="127" height="1278" rgb1="0.8 0.6 0.4" rgb2="0.8 0.6 0.4" markrgb="1 1 1" random="0.01" />
        <texture name="floor_tex"   type="2d"        builtin="checker" rgb1=".2 .3 .4" rgb2=".1 .2 .3" width="100" height="100" />
        <texture name="wood"        type="cube"     file="wood2.png"/>
        <texture name="metal"        type="cube"     file="metal2.png"/>
        <!--Materials-->
        <material name="ur5_mat"        texture="ur5_tex"   shininess="0.9" specular="0.75" reflectance="0.3"/>
        <material name="gripper_mat"    texture="gripper_tex"   shininess="0.9" specular="0.75" reflectance="0.4"/>
        <material name='floor_mat'      texture="floor_tex"  shininess="0.8" texrepeat="10 10" specular="0.7"  reflectance="0.5" />
        <material name='geom'           texture="texgeom"   texuniform="true" />
        <material name="bench_mat"      texture="metal"   shininess="0.1" specular="0.5" reflectance="0.2"/>
        <material name="tablecube"      texture="wood" rgba=".8 .8 .8 1"/>
    </asset>

    <!--Contacts-->
      <contact>
        <exclude body1="gripperpalm" body2="thumb_Link"/>
		<exclude body1="gripperpalm" body2="middle_Link"/>
		<exclude body1="gripperpalm" body2="index_Link"/>
	<exclude body1="gripperpalm" body2="thumb_Link1"/>
		<exclude body1="gripperpalm" body2="middle_Link1"/>
		<exclude body1="gripperpalm" body2="index_Link1"/>
    </contact>

    <!--MODEL DESCRIPTION-->
    <worldbody>
        <!--Lighting parameters-->
        <light name="light3" mode="targetbody" target="box_link" directional="true" pos="1 -1 3" />
        <!-- <light name="light3" mode="targetbody" target="box_link" directional="true" pos="1 1 3" /> -->
        <!--Camera parameters-->
        <camera name="main1" mode="fixed" target="gripperpalm" pos="2 2 2.7" axisangle="2 2 -2 1"/>
        <camera name="top_down" mode="fixed" target="gripperpalm" pos="0 -0.6 2.0" axisangle="2 2 2 0"/>
        <camera name="side" mode="fixed" target="gripperpalm" pos="0.8 -0.6 1.0" quat="0.5 0.5 0.5 0.5"/>
        <!--Floor Property-->
        <geom name='floor' material="floor_mat" pos='0 0 0' size='2.5 2.5 0.1'  type='plane' />


        <body name="box_2_link" pos="0 -0.6 0.435">
            <!--<geom size=".3 .2 .435" type="box" material="bench_mat"/>-->
            <geom size=".29 .19 .03" pos ="0 0 0.4" type="box" material="bench_mat"/>
            <geom size=".29 .19 .03" pos ="0 0 -0.2" type="box" material="bench_mat"/>
            <geom size=".04 .04 .435" pos =".26 .16 0" type="box" material="bench_mat"/>
            <geom size=".04 .04 .435" pos ="-.26 .16 0" type="box" material="bench_mat"/>
            <geom size=".04 .04 .435" pos =".26 -.16 0" type="box" material="bench_mat"/>
            <geom size=".04 .04 .435" pos ="-.26 -.16 0" type="box" material="bench_mat"/>
            <inertial pos="0 0 0" mass="1000" diaginertia="0 0 0" />
        </body>


        <body name="drop_box" pos="0.6 0.0 0.0">
            <geom size=".2 .3 .03" pos ="0 0 0.615" type="box" material="bench_mat"/>
            <geom size=".03 .3 .4" pos ="0.23 0.0 0.4" type="box" material="bench_mat"/>
            <geom size=".03 .3 .4" pos ="-0.23 0.0 0.4" type="box" material="bench_mat"/>
            <geom size=".26 .03 .4" pos ="0.0 0.33 0.4" type="box" material="bench_mat"/>
            <geom size=".26 .03 .4" pos ="0.0 -0.33 0.4" type="box" material="bench_mat"/>
            <inertial pos="0 0 0" mass="1000" diaginertia="0 0 0" />
        </body>


        <!--Robot UR5-->
        <body name="box_link" pos="0 0 0.435">
            <!--<geom size=".3 .2 .435" type="box" material="bench_mat"/>-->
            <geom size=".29 .19 .03" pos ="0 0 0.4" type="box" material="bench_mat"/>
            <geom size=".29 .19 .03" pos ="0 0 -0.2" type="box" material="bench_mat"/>
            <geom size=".04 .04 .435" pos =".26 .16 0" type="box" material="bench_mat"/>
            <geom size=".04 .04 .435" pos ="-.26 .16 0" type="box" material="bench_mat"/>
            <geom size=".04 .04 .435" pos =".26 -.16 0" type="box" material="bench_mat"/>
            <geom size=".04 .04 .435" pos ="-.26 -.16 0" type="box" material="bench_mat"/>
            <inertial pos="0 0 0" mass="1000" diaginertia="0 0 0" />
            <body name="base_link" pos="0 0 0.435">
                <inertial pos="0 0 0" quat="0.5 0.5 -0.5 0.5" mass="4" diaginertia="0.0072 0.00443333 0.00443333" />
                <geom type="mesh"  mesh="base" material="ur5_mat"/>
                <body name="shoulder_link" pos="0 0 0.089159">
                    <inertial pos="0 0 0" mass="3.7" diaginertia="0.0102675 0.0102675 0.00666" />
                    <joint name="shoulder_pan_joint" class="UR5" pos="0 0 0" axis="0 0 1" limited="true" range="-3.14159 3.14159" />
                    <geom type="mesh"  mesh="shoulder" material="ur5_mat"/>
                    <body name="upper_arm_link" pos="0 0.13585 0" quat="0.707107 0 0.707107 0">
                        <inertial pos="0 0 0.28" mass="8.393" diaginertia="0.226891 0.226891 0.0151074" />
                        <joint name="shoulder_lift_joint" class="UR5" pos="0 0 0" axis="0 1 0" limited="true" range="-3.14159 0" /> <!--Range= -3.14159 3.14159-->
                        <geom type="mesh"  mesh="upperarm" material="ur5_mat"/>
                        <body name="forearm_link" pos="0 -0.1197 0.425">
                            <inertial pos="0 0 0.25" mass="2.275" diaginertia="0.0494433 0.0494433 0.004095" />
                            <joint name="elbow_joint" class="UR5" pos="0 0 0" axis="0 1 0" limited="true" range="-3.14159 3.14159" />
                            <geom type="mesh"  mesh="forearm" material="ur5_mat"/>
                            <body name="wrist_1_link" pos="0 0 0.39225" quat="0.707107 0 0.707107 0">
                                <inertial pos="0 0 0" quat="0.5 0.5 -0.5 0.5" mass="1.219" diaginertia="0.21942 0.111173 0.111173" />
                                <joint name="wrist_1_joint" class="UR5e" pos="0 0 0" axis="0 1 0" limited="true" range="-3.14159 3.14159" />
                                <geom type="mesh"  mesh="wrist1" material="ur5_mat"/>
                                <body name="wrist_2_link" pos="0 0.093 0">
                                    <inertial pos="0 0 0" quat="0.5 0.5 -0.5 0.5" mass="1.219" diaginertia="0.21942 0.111173 0.111173" />
                                    <joint name="wrist_2_joint" class="UR5e" pos="0 0 0" axis="0 0 1" limited="true" range="-3.14159 3.14159" />
                                    <geom type="mesh"  mesh="wrist2" material="ur5_mat"/>
                                    <body name="wrist_3_link" pos="0 0 0.09465">
                                        <inertial pos="0 0 0" quat="0.5 0.5 -0.5 0.5" mass="0.1879" diaginertia="0.033822 0.0171365 0.0171365" />
                                        <joint name="wrist_3_joint" class="UR5e" pos="0 0 0" axis="0 1 0" limited="true" range="-3.14159 3.14159" />
                                        <geom type="mesh"  mesh="wrist3" material="ur5_mat"/>
                                        <body name="ee_link" pos="0 0.0823 0" quat="0.707107 0 0 0.707107">
                                            <inertial pos="-0.01 0 0" mass="0.001" diaginertia="1.66667e-08 1.66667e-08 1.66667e-08" />
                                            <geom size="0.005 0.005 0.005" pos="-0.01 0 0" type="box" />
					    <site name="ee" pos="0 0 0" rgba="1 0 0 1" size="0.01" type="sphere" />
                                        </body>
                                        <!--GRIPPER-->
					<body name="tool0" pos="0 0.0823 0" quat="0.707107 -0.707107 0 0">
                                            <inertial pos="0 0.0823 0" quat="0.707107 -0.707107 0 0" mass="0" diaginertia="0 0 0" />
                                            <body name="gripperpalm" pos="0 0 -0.01" quat="0 0 0 1">
                                                <inertial pos="0 0 0" mass="1.3" diaginertia="0.0035 0.0035 0.0035" />
                                                <geom type="mesh"  mesh="base_link" material="gripper_mat"/>
                                                <!--FINGERS-->
                                                <body name="thumb_Link" pos="-0.03 0 0.095" quat="-3.67321e-06 0 0 1">
                                                    <inertial pos="0 0 -0.015" quat="0.5 0.5 -0.5 0.5" mass="0.1" diaginertia="2.5e-05 2.5e-05 1.8e-05" />
                                                    <joint name="thumbjoint0" pos="0 0 0" axis="0 0 1"  range="0 1.0467" />
                                                    <geom type="mesh" material="gripper_mat" mesh="thumb_Link" />
                                                    <body name="thumb_Link1" pos="0 0 0" quat="0.707105 0.707108 0 0">
                                                        <inertial pos="0.016 0 0" quat="0.5 0.5 0.5 0.5" mass="0.047" diaginertia="6.43594e-05 6.06192e-05 4.97928e-06" />
                                                        <joint name="thumbjoint1"  pos="0 0 0" axis="0 0 1" limited="true" range="0 1.5708" />
                                                        <geom  type="mesh" material="gripper_mat" mesh="thumb_Link1" />
                                                        <body name="thumb_Link2" pos="0.032 0 0">
                                                            <inertial pos="0.0275 0 0" quat="0.5 0.5 0.5 0.5" mass="0.03284" diaginertia="2.24866e-05 1.98645e-05 3.47368e-06" />
                                                            <joint name="thumbjoint2"  pos="0 0 0" axis="0 0 1" limited="true" range="0 1.5708" />
                                                            <geom   type="mesh" material="gripper_mat" mesh="thumb_Link2" />
                                                            <body name="thumb_Link3" pos="0.035 0 0" >
								<site name="thumb_site_1" pos="0.035 0 0" size=".01 .01 .01"/>
                                                                <inertial pos="0.0275 0 0" quat="0.5 0.5 0.5 0.5" mass="0.03354" diaginertia="1.43512e-05 1.26412e-05 2.98016e-06" />
                                                                <joint name="thumbjoint3" pos="0 0 0" axis="0 0 1" limited="true" range="0 1.5708" />
                                                                <geom type="mesh" material="gripper_mat" mesh="thumb_Link3" />
                                                            </body>
                                                        </body>
                                                    </body>
                                                </body>
                                                <body name="middle_Link" pos="0.015 0.025 0.095" >
                                                    <inertial pos="0 0.000980762 -0.015" quat="0.5 0.5 -0.5 0.5" mass="0.1" diaginertia="2.5e-05 2.5e-05 1.8e-05" />
                                                    <joint name="mid_joint0" pos="0 0 0" axis="0 0 1" limited="true" range="0 1.0467" />
                                                    <geom type="mesh" material="gripper_mat" mesh="middle_Link" />
                                                    <body name="middle_Link1" pos="0 0 0" quat="0.707105 0.707108 0 0">
                                                        <inertial pos="0.016 0 0" quat="0.5 0.5 0.5 0.5" mass="0.047" diaginertia="6.43594e-05 6.06192e-05 4.97928e-06" />
                                                        <joint name="mid_joint1"  pos="0 0 0" axis="0 0 1" limited="true" range="0 1.2217" />
                                                        <geom   type="mesh" material="gripper_mat" mesh="middle_Link1" />
                                                        <body name="middle_Link2" pos="0.032 0 0">
                                                            <inertial pos="0.0275 0 0" quat="0.5 0.5 0.5 0.5" mass="0.03284" diaginertia="2.24866e-05 1.98645e-05 3.47368e-06" />
                                                            <joint name="mid_joint2"  pos="0 0 0" axis="0 0 1" limited="true" range="0 1.5708" />
                                                            <geom type="mesh" material="gripper_mat" mesh="middle_Link2" />
                                                            <body name="middle_Link3" pos="0.035 0 0">
							    	<site name="middle_site_1" pos="0.035 0 0" size=".011 .011 .011"/>
                                                                <inertial pos="0.0275 0 0" quat="0.5 0.5 0.5 0.5"  mass="0.03354" diaginertia="1.43512e-05 1.26412e-05 2.98016e-06" />
                                                                <joint name="mid_joint3"  pos="0 0 0" axis="0 0 1" limited="true" range="0 1.5708" />
                                                                <geom name="middle_fingertip"type="mesh" material="gripper_mat" mesh="middle_Link3" />
                                                            </body>
                                                        </body>
                                                    </body>
                                                </body>
                                                <body name="index_Link" pos="0.015 -0.026 0.095">
                                                    <inertial pos="0 1.92379e-05 -0.015" quat="0.5 0.5 -0.5 0.5" mass="0.1" diaginertia="2.5e-05 2.5e-05 1.8e-05" />
                                                    <joint name="indexjoint0"  pos="0 0 0" axis="0 0 -1"  limited="true" range="0 1.0467"/> <!--RANGE CAMBIATO (In realtà aggiunto, non c'era ??) A MANO DA ME PER LA STABILITA DEL POLLICE-->
                                                    <geom type="mesh" material="gripper_mat" mesh="index_Link" />
                                                    <body name="index_Link1" pos="0 0 0" quat="0.707105 0.707108 0 0">
                                                        <inertial pos="0.0159972 -0.000299757 0" quat="0.504662 0.504662 0.495294 0.495294" mass="0.047" diaginertia="6.43594e-05 6.06192e-05 4.97928e-06" />
                                                        <joint name="indexjoint1"  pos="0 0 0" axis="0 0 1" limited="true" range="0 1.5708" />
                                                        <geom type="mesh" material="gripper_mat" mesh="index_Link1" />
                                                        <body name="index_Link2" pos="0.031994 -0.00059951 0">
                                                            <inertial pos="0.0274952 -0.000515205 -1.80622e-11" quat="0.504662 0.504662 0.495294 0.495294" mass="0.03284" diaginertia="2.24866e-05 1.98645e-05 3.47368e-06" />
                                                            <joint name="indexjoint2"  pos="0 0 0" axis="0 0 1" limited="true" range="0 1.5708" />
                                                            <geom  type="mesh" material="gripper_mat" mesh="index_Link2" />
                                                            <body name="index_Link3" pos="0.035 0 0">
								<site name="index_site_1" pos="0.035 0 0" size=".011 .011 .011"/>
                                                                <inertial pos="0.0275 0 0" quat="0.5 0.5 0.5 0.5" mass="0.03284" diaginertia="1.43512e-05 1.26412e-05 2.98016e-06" />
                                                                <joint name="indexjoint3" pos="0 0 0" axis="0 0 1" limited="true" range="0 1.57" />
                                                                <geom  name="index_fingertip" type="mesh" material="gripper_mat" mesh="index_Link3" />
                                                            </body>
                                                        </body>
                                                    </body>
                                                </body>
					    </body>
                                        </body>
                                    </body>
                                </body>
                            </body>
                        </body>
                    </body>
                </body>
            </body>
        </body>

   <!--      <body name="pick_box_1" pos="0 -0.6 0.9">
                <freejoint name="tablebox_joint" />
                <geom size="0.03 0.03 0.03" pos="0 0 0.03" type="box" material="tablecube"/>
                <inertial pos="0 0 0.03" mass="0.5" diaginertia="0 0 0" />
        </body> -->

        <body name="box_1" pos=".0 -.6 0.9">
            <joint armature="0" axis="1 0 0" damping="0" limited="false" name="box_1_x" pos="0 0 0" range="-5. 5." stiffness="0" type="slide"/>
            <joint armature="0" axis="0 1 0" damping="0" limited="true" name="box_1_y" pos="0 0 0" range="-5. 5." stiffness="0" type="slide"/>
            <joint armature="0" axis="0 0 1" damping="0" limited="true" name="box_1_z" pos="0 0 0" range="-2. 2." stiffness="0" type="slide"/>
            <!-- <joint armature="0" damping="0" name="box_1_rot" pos="0 0 0" stiffness="0" type="ball"/> -->
            <geom name="box_1" pos="0 0 0" material="tablecube" size="0.02 0.02 0.02" type="box"/>
            <inertial pos="0 0 0" mass="0.2" diaginertia="0.001 0.001 0.001" />
        </body>

        <body name="box_2" pos=".0 -.6 1.0">
            <joint armature="0" axis="1 0 0" damping="0" limited="true" name="box_2_x" pos="0 0 0" range="-5. 5." stiffness="0" type="slide"/>
            <joint armature="0" axis="0 1 0" damping="0" limited="true" name="box_2_y" pos="0 0 0" range="-5. 5." stiffness="0" type="slide"/>
            <joint armature="0" axis="0 0 1" damping="0" limited="true" name="box_2_z" pos="0 0 0" range="-2. 2." stiffness="0" type="slide"/>
            <!-- <joint armature="0" damping="0" name="box_2_rot" pos="0 0 0" stiffness="0" type="ball"/> -->
            <geom name="box_2" pos="0 0 0" rgba="0.0 0.5 0.8 1" size="0.02 0.02 0.02" type="box"/>
            <inertial pos="0 0 0" mass="0.2" diaginertia="0.001 0.001 0.001" />
        </body>

        <body name="box_3" pos=".0 -.6 1.1">
            <joint armature="0" axis="1 0 0" damping="0" limited="true" name="box_3_x" pos="0 0 0" range="-5. 5." stiffness="0" type="slide"/>
            <joint armature="0" axis="0 1 0" damping="0" limited="true" name="box_3_y" pos="0 0 0" range="-5. 5." stiffness="0" type="slide"/>
            <joint armature="0" axis="0 0 1" damping="0" limited="true" name="box_3_z" pos="0 0 0" range="-2. 2." stiffness="0" type="slide"/>
            <!-- <joint armature="0" damping="0" name="box_3_rot" pos="0 0 0" stiffness="0" type="ball"/> -->
            <geom name="box_3" pos="0 0 0" rgba="0.8 0.8 0.1 1" size="0.02 0.02 0.02" type="box"/>
            <inertial pos="0 0 0" mass="0.2" diaginertia="0.001 0.001 0.001" />
        </body>

        <body name="ball_1" pos=".0 -.6 1.2">
            <joint armature="0" axis="1 0 0" damping="0" limited="true" name="ball_1_x" pos="0 0 0" range="-5. 5." stiffness="0" type="slide"/>
            <joint armature="0" axis="0 1 0" damping="0" limited="true" name="ball_1_y" pos="0 0 0" range="-5. 5." stiffness="0" type="slide"/>
            <joint armature="0" axis="0 0 1" damping="0" limited="true" name="ball_1_z" pos="0 0 0" range="-2. 2." stiffness="0" type="slide"/>
            <!-- <joint armature="0" damping="0" name="ball_1_rot" pos="0 0 0" stiffness="0" type="ball"/> -->
            <geom name="ball_1" pos="0 0 0" rgba="0.9 0.2 0.2 1" size=".02" type="sphere"/>
            <inertial pos="0 0 0" mass="0.2" diaginertia="0.001 0.001 0.001" />
        </body>

        <body name="ball_2" pos=".0 -.6 1.3">
            <joint armature="0" axis="1 0 0" damping="0" limited="true" name="ball_2_x" pos="0 0 0" range="-5. 5." stiffness="0" type="slide"/>
            <joint armature="0" axis="0 1 0" damping="0" limited="true" name="ball_2_y" pos="0 0 0" range="-5. 5." stiffness="0" type="slide"/>
            <joint armature="0" axis="0 0 1" damping="0" limited="true" name="ball_2_z" pos="0 0 0" range="-2. 2." stiffness="0" type="slide"/>
            <!-- <joint armature="0" damping="0" name="ball_2_rot" pos="0 0 0" stiffness="0" type="ball"/> -->
            <geom name="ball_2" pos="0 0 0" material="geom" size=".03" type="sphere"/>
            <inertial pos="0 0 0" mass="0.2" diaginertia="0.001 0.001 0.001" />
        </body>

        <body name="ball_3" pos=".0 -.6 1.4">
            <joint armature="0" axis="1 0 0" damping="0" limited="true" name="ball_3_x" pos="0 0 0" range="-5. 5." stiffness="0" type="slide"/>
            <joint armature="0" axis="0 1 0" damping="0" limited="true" name="ball_3_y" pos="0 0 0" range="-5. 5." stiffness="0" type="slide"/>
            <joint armature="0" axis="0 0 1" damping="0" limited="true" name="ball_3_z" pos="0 0 0" range="-2. 2." stiffness="0" type="slide"/>
            <!-- <joint armature="0" damping="0" name="ball_3_rot" pos="0 0 0" stiffness="0" type="ball"/> -->
            <geom name="ball_3" pos="0 0 0" rgba="0.2 0.2 0.5 1" size=".04" type="sphere"/>
            <inertial pos="0 0 0" mass="0.2" diaginertia="0.001 0.001 0.001" />
        </body>

<!--         <body name="cylinder_1" pos=".15 -.55 1.3">
            <joint armature="0" axis="1 0 0" damping="0" limited="true" name="cylinder_1_x" pos="0 0 0" range="-5. 5." ref=".1" stiffness="0" type="slide"/>
            <joint armature="0" axis="0 1 0" damping="0" limited="true" name="cylinder_1_y" pos="0 0 0" range="-5. 5." ref="-.1" stiffness="0" type="slide"/>
            <joint armature="0" axis="0 0 1" damping="0" limited="true" name="cylinder_1_z" pos="0 0 0" range="-2. 2." ref="-.1" stiffness="0" type="slide"/>
            <geom name="cylinder_1" pos="0 0 0" material="geom" size=".025 0.05" type="cylinder"/>
            <inertial pos="0 0 0.01" mass="0.2" diaginertia="0 0 0" />
        </body>
 -->

    </worldbody>
    <tendon>
		<!--Thumbfinger bending-->
		<!-- 大拇指  近:中:远 = 8:4:2
		       	     近:中 = 5:-4 
			     中:远 = -4:6 -->
		<fixed name="thumb_bending1" range="0 1">
			<joint joint="thumbjoint1"  coef="8"/>
			<joint joint="thumbjoint2"  coef="4"/>
			<joint joint="thumbjoint3"  coef="2"/>
		</fixed>
		<fixed name="thumb_bending2" range="0 1">
			<joint joint="thumbjoint1"  coef="5"/>
			<joint joint="thumbjoint2"  coef="-4"/>
			
		</fixed>
		<fixed name="thumb_bending3" range="0 1">
			<joint joint="thumbjoint2"  coef="-4"/>
			<joint joint="thumbjoint3"  coef="6"/>
		</fixed>
		

		<!--Index&MIddlefinger bending-->
		<!--  [8  4  2  8  4  2
		       5  0  0  5  0  0
		       8  4  2 -8 -4 -2
		       5  0  0 -5  0  0
		       0 -4  6  0  0  0
		       0  0  0  0  4 -6] -->	
		<fixed name="IandM_bending1" range="0 1">
			<joint joint="indexjoint1"  coef="8"/>
			<joint joint="indexjoint2"  coef="4"/>
			<joint joint="indexjoint3"  coef="2"/>
			<joint joint="mid_joint1"  coef="8"/>
			<joint joint="mid_joint2"  coef="4"/>
			<joint joint="mid_joint3"  coef="2"/>
		</fixed>
		<fixed name="IandM_bending2" range="0 1">
			<joint joint="indexjoint1"  coef="5"/>
			<joint joint="mid_joint1"  coef="5"/>
		</fixed>
		<fixed name="IandM_bending3" range="0 1">
			<joint joint="indexjoint1"  coef="8"/>
			<joint joint="indexjoint2"  coef="4"/>
			<joint joint="indexjoint3"  coef="2"/>
			<joint joint="mid_joint1"  coef="-8"/>
			<joint joint="mid_joint2"  coef="-4"/>
			<joint joint="mid_joint3"  coef="-2"/>
		</fixed>
		<fixed name="IandM_bending4" range="0 1">
			<joint joint="indexjoint1"  coef="5"/>
			<joint joint="mid_joint1"  coef="-5"/>
		</fixed>
		<fixed name="IandM_bending5" range="0 1">
			<joint joint="indexjoint2"  coef="-4"/>
			<joint joint="indexjoint3"  coef="6"/>
		</fixed>
		<fixed name="IandM_bending6" range="0 1">	
			<joint joint="mid_joint2"  coef="4"/>
			<joint joint="mid_joint3"  coef="-6"/>
		</fixed>




		<!-- Thumb&Middlefinger swing 	
		<fixed name="TandM_swing" range="0 1">
			<joint joint="thumbjoint0"  coef="1"/>
			<joint joint="mid_joint0"  coef="-0.5"/>
		</fixed>-->
		<!-- Index&Middlefinger swing -->	
		<fixed name="IandM_swing" range="0 1">
			<joint joint="indexjoint0"  coef="1"/>
			<joint joint="mid_joint0"  coef="-1"/>
		</fixed>


    </tendon>
    <equality>
		<!-- GRIPPER Couplings -->
		<tendon name="thumb_bending01" 	tendon1="thumb_bending1"/>
		<tendon name="thumb_bending02" 	tendon1="thumb_bending2"/>
		<tendon name="thumb_bending03" 	tendon1="thumb_bending3"/>

		<tendon name="IandM_bending01" 	tendon1="IandM_bending1"/>
		<tendon name="IandM_bending02" 	tendon1="IandM_bending2"/>
		<tendon name="IandM_bending03" 	tendon1="IandM_bending3"/>
		<tendon name="IandM_bending04" 	tendon1="IandM_bending4"/>
		<tendon name="IandM_bending05" 	tendon1="IandM_bending5"/>
		<tendon name="IandM_bending06" 	tendon1="IandM_bending6"/>

		

		<!--<tendon name="TandM_swing01" 	tendon1="TandM_swing"/>
		<tendon name="IandM_swing01" 	tendon1="IandM_swing"/>
		<joint name="IandM_swing" joint1="indexjoint0" joint2="mid_joint0" polycoef="0 1 0 0 0"/>
		<joint name="TandM_swing" joint1="thumbjoint0" joint2="mid_joint0" polycoef="0 0.5 0 0 0"/>-->
    </equality>

    <!--ACTUATORS-->
    <actuator>
        <!--UR5-->
        <position name='shoulder_pan' ctrllimited="true" ctrlrange="-3.14159 3.14159" joint='shoulder_pan_joint' kp="500"/>
        <position name='shoulder_lift' ctrllimited="true" ctrlrange="-3.14159 3.14159" joint='shoulder_lift_joint' kp="500"/>
        <position name='forearm' ctrllimited="true" ctrlrange="-3.14159 3.14159" joint='elbow_joint' kp="500"/>
        <position name='wrist_1' ctrllimited="true" ctrlrange="-3.14159 3.14159" joint='wrist_1_joint' kp="100"/>
        <position name='wrist_2' ctrllimited="true" ctrlrange="-3.14159 3.14159" joint='wrist_2_joint' kp="100"/>
        <position name='wrist_3' ctrllimited="true" ctrlrange="-3.14159 3.14159" joint='wrist_3_joint' kp="100"/>

        
        <!--<velocity name='shoulder_pan_v' class="UR5" joint='shoulder_pan_joint' kv="10"/>-->
        <!--<velocity name='shoulder_lift_v' class="UR5" joint='shoulder_lift_joint' />-->
        <!--<velocity name='forearm_v' class="UR5" joint='elbow_joint' />-->
        <!--<velocity name='wrist_1_v' class="UR5" joint='wrist_1_joint' />-->
        <!--<velocity name='wrist_2_v' class="UR5" joint='wrist_2_joint'/>-->
        <!--<velocity name='wrist_3_v' class="UR5" joint='wrist_3_joint'/>-->

	<position name='thumb_finger_0' ctrllimited="true" kp="5" joint='thumbjoint0' ctrlrange='0 1.2217'/>
	<position name='index_finger_0' ctrllimited="true" kp="5" joint='indexjoint0' ctrlrange='0 1.0467'/>
	<position name='middle_finger_0' ctrllimited="true" kp="5" joint='mid_joint0' ctrlrange='0 1.0467'/>


	<position name='thumbbending' ctrllimited="true" kp="100" tendon="thumb_bending1" ctrlrange='0 12.217'/>
	<position name='IandMbending01' ctrllimited="true" kp="100" tendon="IandM_bending1" ctrlrange='0 12.217'/>	
        <position name='IandMbending02' ctrllimited="true" kp="100" tendon="IandM_bending2" ctrlrange='0 12.217'/>
        

	<!--<position name='thumb_finger_0' ctrllimited="true" kp="5" joint='thumbjoint0' ctrlrange='0 1.2217'/>
	<position name='thumb_finger_1' ctrllimited="true" kp="100" tendon="thumb_bending1" ctrlrange='0 12.217'/>
	<position name='thumb_finger_2' ctrllimited="true" kp="5" joint='thumbjoint2' ctrlrange='0 1.2217'/>
	<position name='thumb_finger_3' ctrllimited="true" kp="5" joint='thumbjoint3' ctrlrange='0 1.2217'/>
        <position name='index_finger_0' ctrllimited="true" kp="5" joint='indexjoint0' ctrlrange='0 1.0467'/>
	<position name='index_finger_1' ctrllimited="true" kp="20" joint='indexjoint1'  ctrlrange='0 1.2217'/>
	<position name='index_finger_2' ctrllimited="true" kp="5" joint='indexjoint2' ctrlrange='0 1.2217'/>
	<position name='index_finger_3' ctrllimited="true" kp="5" joint='indexjoint3' ctrlrange='0 1.2217'/>
	<position name='middle_finger_0' ctrllimited="true" kp="5" joint='mid_joint0' ctrlrange='0 1.0467'/>
	<position name='middle_finger_1' ctrllimited="true" kp="20" joint='mid_joint1' ctrlrange='0 1.2217'/>
	<position name='middle_finger_2' ctrllimited="true" kp="5" joint='mid_joint2' ctrlrange='0 1.2217'/>
	<position name='middle_finger_3' ctrllimited="true" kp="5" joint='mid_joint3' ctrlrange='0 1.2217'/>-->
	<!--Gripper-->
        <!--<motor name='finger_1_T' ctrllimited="true" joint='gripperfinger_1_joint_1' ctrlrange='-0.5 .8' gear="20"/>-->
        <!--<motor name='finger_2_T' ctrllimited="true" joint='gripperfinger_2_joint_1' ctrlrange='-0.5 .8' gear="20"/>-->
        <!--<motor name='middle_finger_T'  ctrllimited="true" joint='gripperfinger_middle_joint_1' ctrlrange='-0.5 .8' gear="20"/>-->
        <!--<motor name='finger_scissor_T' ctrllimited="true" joint='gripperpalm_finger_1_joint' ctrlrange="-0.8 0.8" gear="15"/>-->   

     <!--    
        <motor name='finger_1_T' ctrllimited="true" joint='gripperfinger_1_joint_1' ctrlrange='-0.1 .8' gear="20"/>
        <motor name='finger_2_T' ctrllimited="true" joint='gripperfinger_2_joint_1' ctrlrange='-0.1 .8' gear="20"/>
        <motor name='middle_finger_T'  ctrllimited="true" joint='gripperfinger_middle_joint_1' ctrlrange='-0.1 .8' gear="20"/>
        <motor name='finger_scissor_T' ctrllimited="true" joint='gripperpalm_finger_1_joint' ctrlrange="-0.8 0.8" gear="15"/> -->
    </actuator>
    <sensor>
	<touch name="thumb_finger_01" site="thumb_site_1"/>
	<touch name="middle_finger_01" site="middle_site_1"/>
	<touch name="index_finger_01" site="index_site_1"/>
    </sensor>
</mujoco>
